Workbook

Sheet Read me
A1: Model template
A3: What this is | C3: A starting point for your own model, with the same three parts as the example models: types, plant and bindings.
A4: What is in it now | C4: Empty, ready for your own model. The three type sheets keep the example's types as a start: keep the ones you need, change the rest. The example copy (model-template.xlsx) shows a filled-in model.
A5: Yellow cells | C5: Yours to fill in. Most columns offer a drop-down list of the names already defined.
A6: Grey cells | C6: Formulas. Do not type in them. Each Check column shows "ok" or says what is wrong with that row.
A7: Room | C7: Each sheet checks rows 2 to 201. Start small: about ten assets is enough.
A8: Topics | C8: Built for you on the Bindings sheet, the same way as the example files: a measurement goes under the prefix below, then the asset's path and its short name; a state or alarm goes under the second prefix, then the top level, the asset and its short name. An asset can have a shorter name for topics. Nothing is typed twice.
A9: Topic prefix for measurements | B9: example/telemetry/wastewater | C9: Change this to your own.
A10: Topic prefix for states and alarms | B10: example/events/wastewater | C10: Change this to your own.
A11: Which copy is the source | C11: This spreadsheet is a starting point. Once the model is kept as files or in a tool, name that copy as the source and stop editing this one.
A12: Never put in this file | C12: Passwords, network addresses, real locations of critical equipment. If you fill in the Bindings sheet with real addresses, keep the file inside your organisation.
A13: Left out to keep it small | C13: Records such as procedures and drawings, quality limits, and derived values. The example files show how to add them later.
A14: Everything here is invented | C14: No name, tag, topic or value describes a real system.
A16: Sheet | B16: Rows filled | C16: Rows with a problem
A17: 1 Types | B17: =COUNTA('1 Types'!$A$2:$A$201) -> 18 | C17: =SUMPRODUCT(('1 Types'!$G$2:$G$201<>"ok")*('1 Types'!$A$2:$A$201<>"")) -> 0
A18: 1 Measurement types | B18: =COUNTA('1 Measurement types'!$A$2:$A$201) -> 12 | C18: =SUMPRODUCT(('1 Measurement types'!$E$2:$E$201<>"ok")*('1 Measurement types'!$A$2:$A$201<>"")) -> 0
A19: 1 Relationship types | B19: =COUNTA('1 Relationship types'!$A$2:$A$201) -> 4 | C19: =SUMPRODUCT(('1 Relationship types'!$D$2:$D$201<>"ok")*('1 Relationship types'!$A$2:$A$201<>"")) -> 0
A20: 2 Assets | B20: =COUNTA('2 Assets'!$A$2:$A$201) -> 0 | C20: =SUMPRODUCT(('2 Assets'!$G$2:$G$201<>"ok")*('2 Assets'!$A$2:$A$201<>"")) -> 0
A21: 2 Measurements | B21: =COUNTA('2 Measurements'!$A$2:$A$201) -> 0 | C21: =SUMPRODUCT(('2 Measurements'!$I$2:$I$201<>"ok")*('2 Measurements'!$A$2:$A$201<>"")) -> 0
A22: 2 Relationships | B22: =COUNTA('2 Relationships'!$A$2:$A$201) -> 0 | C22: =SUMPRODUCT(('2 Relationships'!$D$2:$D$201<>"ok")*('2 Relationships'!$A$2:$A$201<>"")) -> 0
A23: 3 Bindings | B23: =COUNTA('3 Bindings'!$A$2:$A$201) -> 0 | C23: =SUMPRODUCT(('3 Bindings'!$E$2:$E$201<>"ok")*('3 Bindings'!$A$2:$A$201<>"")) -> 0
A24: All sheets | B24: =SUM(B17:B23) -> 34 | C24: =SUM(C17:C23) -> 0
A25: Measurements not yet on the Bindings sheet | B25: =COUNTIF('2 Measurements'!$H$2:$H$201,"not yet") -> 0 | C25: Not a problem during a first session. Fill these in afterwards.
A27: What the checks catch | C27: Names that do not match exactly (capitals count), duplicates, an asset with no parent that is not a site or network, a parent loop or more than five levels, a kind or measurement type that is not defined, a missing or wrong unit, and a topic used twice.
A28: What they cannot catch | C28: Whether a relationship is true, or whether a value is bound to the right address. Only people who know the plant can check that.

Sheet 1 Types
A1: Type | B1: Is a kind of (extends) | C1: What it means | D1: Shared or local | E1: Can sit at the top, with no parent | F1: Standard followed, or to check first | G1: Check (do not edit)
A2: Location | C2: A place: a site, a linear network, or a hydraulic region | D2: Shared | G2: =IF(A2="","",IF(SUMPRODUCT(--EXACT($A$2:$A$201,A2))>1,"Duplicate type",IF(OR(B2="",SUMPRODUCT(--EXACT($A$2:$A$201,B2))>0),IF(OR(E2="",E2="yes"),"ok","Top: type yes or leave blank"),"The type it extends is not in this list"))) -> ok
A3: Function | C3: A named slot in the site -> area -> equipment tree | D3: Shared | G3: =IF(A3="","",IF(SUMPRODUCT(--EXACT($A$2:$A$201,A3))>1,"Duplicate type",IF(OR(B3="",SUMPRODUCT(--EXACT($A$2:$A$201,B3))>0),IF(OR(E3="",E3="yes"),"ok","Top: type yes or leave blank"),"The type it extends is not in this list"))) -> ok
A4: Asset | C4: A physical thing with its own identity, installed at one Function | D4: Shared | G4: =IF(A4="","",IF(SUMPRODUCT(--EXACT($A$2:$A$201,A4))>1,"Duplicate type",IF(OR(B4="",SUMPRODUCT(--EXACT($A$2:$A$201,B4))>0),IF(OR(E4="",E4="yes"),"ok","Top: type yes or leave blank"),"The type it extends is not in this list"))) -> ok
A5: Site | B5: Location | C5: ISA-95 site: a plant or a station | D5: Shared | E5: yes | F5: ISA-95 equipment hierarchy | G5: =IF(A5="","",IF(SUMPRODUCT(--EXACT($A$2:$A$201,A5))>1,"Duplicate type",IF(OR(B5="",SUMPRODUCT(--EXACT($A$2:$A$201,B5))>0),IF(OR(E5="",E5="yes"),"ok","Top: type yes or leave blank"),"The type it extends is not in this list"))) -> ok
A6: Network | B6: Location | C6: A linear network (transmission mains) operated as one place | D6: Shared | E6: yes | G6: =IF(A6="","",IF(SUMPRODUCT(--EXACT($A$2:$A$201,A6))>1,"Duplicate type",IF(OR(B6="",SUMPRODUCT(--EXACT($A$2:$A$201,B6))>0),IF(OR(E6="",E6="yes"),"ok","Top: type yes or leave blank"),"The type it extends is not in this list"))) -> ok
A7: Area | B7: Function | C7: ISA-95 area: a process area of a site | D7: Shared | F7: ISA-95 equipment hierarchy | G7: =IF(A7="","",IF(SUMPRODUCT(--EXACT($A$2:$A$201,A7))>1,"Duplicate type",IF(OR(B7="",SUMPRODUCT(--EXACT($A$2:$A$201,B7))>0),IF(OR(E7="",E7="yes"),"ok","Top: type yes or leave blank"),"The type it extends is not in this list"))) -> ok
A8: Equipment | B8: Function | C8: A position in an area | D8: Shared | F8: ISA-95 equipment hierarchy (the levels below area) | G8: =IF(A8="","",IF(SUMPRODUCT(--EXACT($A$2:$A$201,A8))>1,"Duplicate type",IF(OR(B8="",SUMPRODUCT(--EXACT($A$2:$A$201,B8))>0),IF(OR(E8="",E8="yes"),"ok","Top: type yes or leave blank"),"The type it extends is not in this list"))) -> ok
A9: Reservoir | B9: Equipment | C9: A storage cell, clearwell or reservoir | D9: Shared | F9: Smart Data Models for water | G9: =IF(A9="","",IF(SUMPRODUCT(--EXACT($A$2:$A$201,A9))>1,"Duplicate type",IF(OR(B9="",SUMPRODUCT(--EXACT($A$2:$A$201,B9))>0),IF(OR(E9="",E9="yes"),"ok","Top: type yes or leave blank"),"The type it extends is not in this list"))) -> ok
A10: Pump | B10: Equipment | C10: A pump POSITION (duty role, run state, speed) | D10: Shared | F10: OPC 40223, OPC UA for Pumps and Vacuum Pumps | G10: =IF(A10="","",IF(SUMPRODUCT(--EXACT($A$2:$A$201,A10))>1,"Duplicate type",IF(OR(B10="",SUMPRODUCT(--EXACT($A$2:$A$201,B10))>0),IF(OR(E10="",E10="yes"),"ok","Top: type yes or leave blank"),"The type it extends is not in this list"))) -> ok
A11: Main | B11: Equipment | C11: A section of transmission main between two places | D11: Shared | F11: Smart Data Models for water | G11: =IF(A11="","",IF(SUMPRODUCT(--EXACT($A$2:$A$201,A11))>1,"Duplicate type",IF(OR(B11="",SUMPRODUCT(--EXACT($A$2:$A$201,B11))>0),IF(OR(E11="",E11="yes"),"ok","Top: type yes or leave blank"),"The type it extends is not in this list"))) -> ok
A12: Instrument | B12: Asset | C12: An online analyzer or transmitter | D12: Shared | F12: ISA-5.1, instrument symbols and identification | G12: =IF(A12="","",IF(SUMPRODUCT(--EXACT($A$2:$A$201,A12))>1,"Duplicate type",IF(OR(B12="",SUMPRODUCT(--EXACT($A$2:$A$201,B12))>0),IF(OR(E12="",E12="yes"),"ok","Top: type yes or leave blank"),"The type it extends is not in this list"))) -> ok
A13: WetWell | B13: Reservoir | C13: A chamber that collects sewage ahead of the pumps | D13: Local | G13: =IF(A13="","",IF(SUMPRODUCT(--EXACT($A$2:$A$201,A13))>1,"Duplicate type",IF(OR(B13="",SUMPRODUCT(--EXACT($A$2:$A$201,B13))>0),IF(OR(E13="",E13="yes"),"ok","Top: type yes or leave blank"),"The type it extends is not in this list"))) -> ok
A14: Forcemain | B14: Main | C14: A pressurised sewer from a pumping station | D14: Local | G14: =IF(A14="","",IF(SUMPRODUCT(--EXACT($A$2:$A$201,A14))>1,"Duplicate type",IF(OR(B14="",SUMPRODUCT(--EXACT($A$2:$A$201,B14))>0),IF(OR(E14="",E14="yes"),"ok","Top: type yes or leave blank"),"The type it extends is not in this list"))) -> ok
A15: Screen | B15: Equipment | C15: A screen that removes debris at the plant inlet | D15: Local | G15: =IF(A15="","",IF(SUMPRODUCT(--EXACT($A$2:$A$201,A15))>1,"Duplicate type",IF(OR(B15="",SUMPRODUCT(--EXACT($A$2:$A$201,B15))>0),IF(OR(E15="",E15="yes"),"ok","Top: type yes or leave blank"),"The type it extends is not in this list"))) -> ok
A16: GritChamber | B16: Equipment | C16: A chamber where sand and grit settle out after screening | D16: Local | G16: =IF(A16="","",IF(SUMPRODUCT(--EXACT($A$2:$A$201,A16))>1,"Duplicate type",IF(OR(B16="",SUMPRODUCT(--EXACT($A$2:$A$201,B16))>0),IF(OR(E16="",E16="yes"),"ok","Top: type yes or leave blank"),"The type it extends is not in this list"))) -> ok
A17: Blower | B17: Equipment | C17: A blower that supplies air to an aeration basin | D17: Local | G17: =IF(A17="","",IF(SUMPRODUCT(--EXACT($A$2:$A$201,A17))>1,"Duplicate type",IF(OR(B17="",SUMPRODUCT(--EXACT($A$2:$A$201,B17))>0),IF(OR(E17="",E17="yes"),"ok","Top: type yes or leave blank"),"The type it extends is not in this list"))) -> ok
A18: AerationBasin | B18: Equipment | C18: A basin where air is added for biological treatment | D18: Local | G18: =IF(A18="","",IF(SUMPRODUCT(--EXACT($A$2:$A$201,A18))>1,"Duplicate type",IF(OR(B18="",SUMPRODUCT(--EXACT($A$2:$A$201,B18))>0),IF(OR(E18="",E18="yes"),"ok","Top: type yes or leave blank"),"The type it extends is not in this list"))) -> ok
A19: Clarifier | B19: Equipment | C19: A tank where solids settle out | D19: Local | G19: =IF(A19="","",IF(SUMPRODUCT(--EXACT($A$2:$A$201,A19))>1,"Duplicate type",IF(OR(B19="",SUMPRODUCT(--EXACT($A$2:$A$201,B19))>0),IF(OR(E19="",E19="yes"),"ok","Top: type yes or leave blank"),"The type it extends is not in this list"))) -> ok
G20: =IF(A20="","",IF(SUMPRODUCT(--EXACT($A$2:$A$201,A20))>1,"Duplicate type",IF(OR(B20="",SUMPRODUCT(--EXACT($A$2:$A$201,B20))>0),IF(OR(E20="",E20="yes"),"ok","Top: type yes or leave blank"),"The type it extends is not in this list")))
G21: =IF(A21="","",IF(SUMPRODUCT(--EXACT($A$2:$A$201,A21))>1,"Duplicate type",IF(OR(B21="",SUMPRODUCT(--EXACT($A$2:$A$201,B21))>0),IF(OR(E21="",E21="yes"),"ok","Top: type yes or leave blank"),"The type it extends is not in this list")))
G22: =IF(A22="","",IF(SUMPRODUCT(--EXACT($A$2:$A$201,A22))>1,"Duplicate type",IF(OR(B22="",SUMPRODUCT(--EXACT($A$2:$A$201,B22))>0),IF(OR(E22="",E22="yes"),"ok","Top: type yes or leave blank"),"The type it extends is not in this list")))
G23: =IF(A23="","",IF(SUMPRODUCT(--EXACT($A$2:$A$201,A23))>1,"Duplicate type",IF(OR(B23="",SUMPRODUCT(--EXACT($A$2:$A$201,B23))>0),IF(OR(E23="",E23="yes"),"ok","Top: type yes or leave blank"),"The type it extends is not in this list")))
G24: =IF(A24="","",IF(SUMPRODUCT(--EXACT($A$2:$A$201,A24))>1,"Duplicate type",IF(OR(B24="",SUMPRODUCT(--EXACT($A$2:$A$201,B24))>0),IF(OR(E24="",E24="yes"),"ok","Top: type yes or leave blank"),"The type it extends is not in this list")))
G25: =IF(A25="","",IF(SUMPRODUCT(--EXACT($A$2:$A$201,A25))>1,"Duplicate type",IF(OR(B25="",SUMPRODUCT(--EXACT($A$2:$A$201,B25))>0),IF(OR(E25="",E25="yes"),"ok","Top: type yes or leave blank"),"The type it extends is not in this list")))
G26: =IF(A26="","",IF(SUMPRODUCT(--EXACT($A$2:$A$201,A26))>1,"Duplicate type",IF(OR(B26="",SUMPRODUCT(--EXACT($A$2:$A$201,B26))>0),IF(OR(E26="",E26="yes"),"ok","Top: type yes or leave blank"),"The type it extends is not in this list")))
G27: =IF(A27="","",IF(SUMPRODUCT(--EXACT($A$2:$A$201,A27))>1,"Duplicate type",IF(OR(B27="",SUMPRODUCT(--EXACT($A$2:$A$201,B27))>0),IF(OR(E27="",E27="yes"),"ok","Top: type yes or leave blank"),"The type it extends is not in this list")))
G28: =IF(A28="","",IF(SUMPRODUCT(--EXACT($A$2:$A$201,A28))>1,"Duplicate type",IF(OR(B28="",SUMPRODUCT(--EXACT($A$2:$A$201,B28))>0),IF(OR(E28="",E28="yes"),"ok","Top: type yes or leave blank"),"The type it extends is not in this list")))
G29: =IF(A29="","",IF(SUMPRODUCT(--EXACT($A$2:$A$201,A29))>1,"Duplicate type",IF(OR(B29="",SUMPRODUCT(--EXACT($A$2:$A$201,B29))>0),IF(OR(E29="",E29="yes"),"ok","Top: type yes or leave blank"),"The type it extends is not in this list")))
G30: =IF(A30="","",IF(SUMPRODUCT(--EXACT($A$2:$A$201,A30))>1,"Duplicate type",IF(OR(B30="",SUMPRODUCT(--EXACT($A$2:$A$201,B30))>0),IF(OR(E30="",E30="yes"),"ok","Top: type yes or leave blank"),"The type it extends is not in this list")))
G31: =IF(A31="","",IF(SUMPRODUCT(--EXACT($A$2:$A$201,A31))>1,"Duplicate type",IF(OR(B31="",SUMPRODUCT(--EXACT($A$2:$A$201,B31))>0),IF(OR(E31="",E31="yes"),"ok","Top: type yes or leave blank"),"The type it extends is not in this list")))
... G201: =IF(A201="","",IF(SUMPRODUCT(--EXACT($A$2:$A$201,A201))>1,"Duplicate type",IF(OR(B201="",SUMPRODUCT(--EXACT($A$2:$A$201,B201))>0),IF(OR(E201="",E201="yes"),"ok","Top: type yes or leave blank"),"The type it extends is not in this list")))

Sheet 1 Measurement types
A1: Measurement type | B1: Kind | C1: Unit (blank for a state or alarm) | D1: What it means | E1: Check (do not edit)
A2: Pressure | B2: Measurement | C2: kPa | D2: Water pressure | E2: =IF(A2="","",IF(SUMPRODUCT(--EXACT($A$2:$A$201,A2))>1,"Duplicate type",IF(AND(B2<>"Measurement",B2<>"State or alarm"),"Kind must be Measurement or State or alarm",IF(AND(B2="Measurement",C2=""),"A measurement type needs a unit",IF(AND(B2="State or alarm",C2<>""),"A state or alarm has no unit","ok"))))) -> ok
A3: Flow | B3: Measurement | C3: L/s | D3: Volumetric flow rate | E3: =IF(A3="","",IF(SUMPRODUCT(--EXACT($A$2:$A$201,A3))>1,"Duplicate type",IF(AND(B3<>"Measurement",B3<>"State or alarm"),"Kind must be Measurement or State or alarm",IF(AND(B3="Measurement",C3=""),"A measurement type needs a unit",IF(AND(B3="State or alarm",C3<>""),"A state or alarm has no unit","ok"))))) -> ok
A4: Level | B4: Measurement | C4: m | D4: Liquid level | E4: =IF(A4="","",IF(SUMPRODUCT(--EXACT($A$2:$A$201,A4))>1,"Duplicate type",IF(AND(B4<>"Measurement",B4<>"State or alarm"),"Kind must be Measurement or State or alarm",IF(AND(B4="Measurement",C4=""),"A measurement type needs a unit",IF(AND(B4="State or alarm",C4<>""),"A state or alarm has no unit","ok"))))) -> ok
A5: DissolvedOxygen | B5: Measurement | C5: mg/L | D5: Dissolved oxygen | E5: =IF(A5="","",IF(SUMPRODUCT(--EXACT($A$2:$A$201,A5))>1,"Duplicate type",IF(AND(B5<>"Measurement",B5<>"State or alarm"),"Kind must be Measurement or State or alarm",IF(AND(B5="Measurement",C5=""),"A measurement type needs a unit",IF(AND(B5="State or alarm",C5<>""),"A state or alarm has no unit","ok"))))) -> ok
A6: DifferentialLevel | B6: Measurement | C6: m | D6: Difference in level across a screen | E6: =IF(A6="","",IF(SUMPRODUCT(--EXACT($A$2:$A$201,A6))>1,"Duplicate type",IF(AND(B6<>"Measurement",B6<>"State or alarm"),"Kind must be Measurement or State or alarm",IF(AND(B6="Measurement",C6=""),"A measurement type needs a unit",IF(AND(B6="State or alarm",C6<>""),"A state or alarm has no unit","ok"))))) -> ok
A7: MotorCurrent | B7: Measurement | C7: A | D7: Motor current | E7: =IF(A7="","",IF(SUMPRODUCT(--EXACT($A$2:$A$201,A7))>1,"Duplicate type",IF(AND(B7<>"Measurement",B7<>"State or alarm"),"Kind must be Measurement or State or alarm",IF(AND(B7="Measurement",C7=""),"A measurement type needs a unit",IF(AND(B7="State or alarm",C7<>""),"A state or alarm has no unit","ok"))))) -> ok
A8: PumpRunState | B8: State or alarm | D8: Pump run state | E8: =IF(A8="","",IF(SUMPRODUCT(--EXACT($A$2:$A$201,A8))>1,"Duplicate type",IF(AND(B8<>"Measurement",B8<>"State or alarm"),"Kind must be Measurement or State or alarm",IF(AND(B8="Measurement",C8=""),"A measurement type needs a unit",IF(AND(B8="State or alarm",C8<>""),"A state or alarm has no unit","ok"))))) -> ok
A9: PumpTripAlarm | B9: State or alarm | D9: Pump protection trip | E9: =IF(A9="","",IF(SUMPRODUCT(--EXACT($A$2:$A$201,A9))>1,"Duplicate type",IF(AND(B9<>"Measurement",B9<>"State or alarm"),"Kind must be Measurement or State or alarm",IF(AND(B9="Measurement",C9=""),"A measurement type needs a unit",IF(AND(B9="State or alarm",C9<>""),"A state or alarm has no unit","ok"))))) -> ok
A10: FailToStartAlarm | B10: State or alarm | D10: A machine was commanded to start and did not | E10: =IF(A10="","",IF(SUMPRODUCT(--EXACT($A$2:$A$201,A10))>1,"Duplicate type",IF(AND(B10<>"Measurement",B10<>"State or alarm"),"Kind must be Measurement or State or alarm",IF(AND(B10="Measurement",C10=""),"A measurement type needs a unit",IF(AND(B10="State or alarm",C10<>""),"A state or alarm has no unit","ok"))))) -> ok
A11: MainState | B11: State or alarm | D11: Operating state of a transmission main section | E11: =IF(A11="","",IF(SUMPRODUCT(--EXACT($A$2:$A$201,A11))>1,"Duplicate type",IF(AND(B11<>"Measurement",B11<>"State or alarm"),"Kind must be Measurement or State or alarm",IF(AND(B11="Measurement",C11=""),"A measurement type needs a unit",IF(AND(B11="State or alarm",C11<>""),"A state or alarm has no unit","ok"))))) -> ok
A12: HighLevelAlarm | B12: State or alarm | D12: Level above its alarm limit | E12: =IF(A12="","",IF(SUMPRODUCT(--EXACT($A$2:$A$201,A12))>1,"Duplicate type",IF(AND(B12<>"Measurement",B12<>"State or alarm"),"Kind must be Measurement or State or alarm",IF(AND(B12="Measurement",C12=""),"A measurement type needs a unit",IF(AND(B12="State or alarm",C12<>""),"A state or alarm has no unit","ok"))))) -> ok
A13: HighHighLevelAlarm | B13: State or alarm | D13: Level above its second, higher alarm limit | E13: =IF(A13="","",IF(SUMPRODUCT(--EXACT($A$2:$A$201,A13))>1,"Duplicate type",IF(AND(B13<>"Measurement",B13<>"State or alarm"),"Kind must be Measurement or State or alarm",IF(AND(B13="Measurement",C13=""),"A measurement type needs a unit",IF(AND(B13="State or alarm",C13<>""),"A state or alarm has no unit","ok"))))) -> ok
E14: =IF(A14="","",IF(SUMPRODUCT(--EXACT($A$2:$A$201,A14))>1,"Duplicate type",IF(AND(B14<>"Measurement",B14<>"State or alarm"),"Kind must be Measurement or State or alarm",IF(AND(B14="Measurement",C14=""),"A measurement type needs a unit",IF(AND(B14="State or alarm",C14<>""),"A state or alarm has no unit","ok")))))
E15: =IF(A15="","",IF(SUMPRODUCT(--EXACT($A$2:$A$201,A15))>1,"Duplicate type",IF(AND(B15<>"Measurement",B15<>"State or alarm"),"Kind must be Measurement or State or alarm",IF(AND(B15="Measurement",C15=""),"A measurement type needs a unit",IF(AND(B15="State or alarm",C15<>""),"A state or alarm has no unit","ok")))))
E16: =IF(A16="","",IF(SUMPRODUCT(--EXACT($A$2:$A$201,A16))>1,"Duplicate type",IF(AND(B16<>"Measurement",B16<>"State or alarm"),"Kind must be Measurement or State or alarm",IF(AND(B16="Measurement",C16=""),"A measurement type needs a unit",IF(AND(B16="State or alarm",C16<>""),"A state or alarm has no unit","ok")))))
E17: =IF(A17="","",IF(SUMPRODUCT(--EXACT($A$2:$A$201,A17))>1,"Duplicate type",IF(AND(B17<>"Measurement",B17<>"State or alarm"),"Kind must be Measurement or State or alarm",IF(AND(B17="Measurement",C17=""),"A measurement type needs a unit",IF(AND(B17="State or alarm",C17<>""),"A state or alarm has no unit","ok")))))
E18: =IF(A18="","",IF(SUMPRODUCT(--EXACT($A$2:$A$201,A18))>1,"Duplicate type",IF(AND(B18<>"Measurement",B18<>"State or alarm"),"Kind must be Measurement or State or alarm",IF(AND(B18="Measurement",C18=""),"A measurement type needs a unit",IF(AND(B18="State or alarm",C18<>""),"A state or alarm has no unit","ok")))))
E19: =IF(A19="","",IF(SUMPRODUCT(--EXACT($A$2:$A$201,A19))>1,"Duplicate type",IF(AND(B19<>"Measurement",B19<>"State or alarm"),"Kind must be Measurement or State or alarm",IF(AND(B19="Measurement",C19=""),"A measurement type needs a unit",IF(AND(B19="State or alarm",C19<>""),"A state or alarm has no unit","ok")))))
E20: =IF(A20="","",IF(SUMPRODUCT(--EXACT($A$2:$A$201,A20))>1,"Duplicate type",IF(AND(B20<>"Measurement",B20<>"State or alarm"),"Kind must be Measurement or State or alarm",IF(AND(B20="Measurement",C20=""),"A measurement type needs a unit",IF(AND(B20="State or alarm",C20<>""),"A state or alarm has no unit","ok")))))
E21: =IF(A21="","",IF(SUMPRODUCT(--EXACT($A$2:$A$201,A21))>1,"Duplicate type",IF(AND(B21<>"Measurement",B21<>"State or alarm"),"Kind must be Measurement or State or alarm",IF(AND(B21="Measurement",C21=""),"A measurement type needs a unit",IF(AND(B21="State or alarm",C21<>""),"A state or alarm has no unit","ok")))))
E22: =IF(A22="","",IF(SUMPRODUCT(--EXACT($A$2:$A$201,A22))>1,"Duplicate type",IF(AND(B22<>"Measurement",B22<>"State or alarm"),"Kind must be Measurement or State or alarm",IF(AND(B22="Measurement",C22=""),"A measurement type needs a unit",IF(AND(B22="State or alarm",C22<>""),"A state or alarm has no unit","ok")))))
E23: =IF(A23="","",IF(SUMPRODUCT(--EXACT($A$2:$A$201,A23))>1,"Duplicate type",IF(AND(B23<>"Measurement",B23<>"State or alarm"),"Kind must be Measurement or State or alarm",IF(AND(B23="Measurement",C23=""),"A measurement type needs a unit",IF(AND(B23="State or alarm",C23<>""),"A state or alarm has no unit","ok")))))
E24: =IF(A24="","",IF(SUMPRODUCT(--EXACT($A$2:$A$201,A24))>1,"Duplicate type",IF(AND(B24<>"Measurement",B24<>"State or alarm"),"Kind must be Measurement or State or alarm",IF(AND(B24="Measurement",C24=""),"A measurement type needs a unit",IF(AND(B24="State or alarm",C24<>""),"A state or alarm has no unit","ok")))))
E25: =IF(A25="","",IF(SUMPRODUCT(--EXACT($A$2:$A$201,A25))>1,"Duplicate type",IF(AND(B25<>"Measurement",B25<>"State or alarm"),"Kind must be Measurement or State or alarm",IF(AND(B25="Measurement",C25=""),"A measurement type needs a unit",IF(AND(B25="State or alarm",C25<>""),"A state or alarm has no unit","ok")))))
... E201: =IF(A201="","",IF(SUMPRODUCT(--EXACT($A$2:$A$201,A201))>1,"Duplicate type",IF(AND(B201<>"Measurement",B201<>"State or alarm"),"Kind must be Measurement or State or alarm",IF(AND(B201="Measurement",C201=""),"A measurement type needs a unit",IF(AND(B201="State or alarm",C201<>""),"A state or alarm has no unit","ok")))))

Sheet 1 Relationship types
A1: Relationship | B1: Its reverse | C1: What it means | D1: Check (do not edit)
A2: Feeds | B2: FedBy | C2: The process stream (water or sewage) passes from one position to the next | D2: =IF(A2="","",IF(B2="","Give the reverse a name",IF(SUMPRODUCT(--EXACT($A$2:$A$201,A2))>1,"Duplicate","ok"))) -> ok
A3: SuppliesAir | B3: AirSuppliedBy | C3: A compressor or blower supplies air to a vessel or basin | D3: =IF(A3="","",IF(B3="","Give the reverse a name",IF(SUMPRODUCT(--EXACT($A$2:$A$201,A3))>1,"Duplicate","ok"))) -> ok
A4: Protects | B4: ProtectedBy | C4: A protective device guards a position (a surge vessel guards a main) | D4: =IF(A4="","",IF(B4="","Give the reverse a name",IF(SUMPRODUCT(--EXACT($A$2:$A$201,A4))>1,"Duplicate","ok"))) -> ok
A5: Monitors | B5: MonitoredBy | C5: An instrument observes a position | D5: =IF(A5="","",IF(B5="","Give the reverse a name",IF(SUMPRODUCT(--EXACT($A$2:$A$201,A5))>1,"Duplicate","ok"))) -> ok
D6: =IF(A6="","",IF(B6="","Give the reverse a name",IF(SUMPRODUCT(--EXACT($A$2:$A$201,A6))>1,"Duplicate","ok")))
D7: =IF(A7="","",IF(B7="","Give the reverse a name",IF(SUMPRODUCT(--EXACT($A$2:$A$201,A7))>1,"Duplicate","ok")))
D8: =IF(A8="","",IF(B8="","Give the reverse a name",IF(SUMPRODUCT(--EXACT($A$2:$A$201,A8))>1,"Duplicate","ok")))
D9: =IF(A9="","",IF(B9="","Give the reverse a name",IF(SUMPRODUCT(--EXACT($A$2:$A$201,A9))>1,"Duplicate","ok")))
D10: =IF(A10="","",IF(B10="","Give the reverse a name",IF(SUMPRODUCT(--EXACT($A$2:$A$201,A10))>1,"Duplicate","ok")))
D11: =IF(A11="","",IF(B11="","Give the reverse a name",IF(SUMPRODUCT(--EXACT($A$2:$A$201,A11))>1,"Duplicate","ok")))
D12: =IF(A12="","",IF(B12="","Give the reverse a name",IF(SUMPRODUCT(--EXACT($A$2:$A$201,A12))>1,"Duplicate","ok")))
D13: =IF(A13="","",IF(B13="","Give the reverse a name",IF(SUMPRODUCT(--EXACT($A$2:$A$201,A13))>1,"Duplicate","ok")))
D14: =IF(A14="","",IF(B14="","Give the reverse a name",IF(SUMPRODUCT(--EXACT($A$2:$A$201,A14))>1,"Duplicate","ok")))
D15: =IF(A15="","",IF(B15="","Give the reverse a name",IF(SUMPRODUCT(--EXACT($A$2:$A$201,A15))>1,"Duplicate","ok")))
D16: =IF(A16="","",IF(B16="","Give the reverse a name",IF(SUMPRODUCT(--EXACT($A$2:$A$201,A16))>1,"Duplicate","ok")))
D17: =IF(A17="","",IF(B17="","Give the reverse a name",IF(SUMPRODUCT(--EXACT($A$2:$A$201,A17))>1,"Duplicate","ok")))
... D201: =IF(A201="","",IF(B201="","Give the reverse a name",IF(SUMPRODUCT(--EXACT($A$2:$A$201,A201))>1,"Duplicate","ok")))

Sheet 2 Assets
A1: Asset ID | B1: Display name | C1: Type | D1: Parent (blank only for a site or network) | E1: Name in topics (optional; blank uses the ID) | F1: Topic path (do not edit) | G1: Check (do not edit) | H1: Parent | I1: Its parent | J1: Next up | K1: Next up | L1: Too deep or a loop? | M1: Top level
F2: =IF(A2="","",IF(K2<>"",IFERROR(IF(INDEX($E$2:$E$201,MATCH(K2,$A$2:$A$201,0))="",K2,INDEX($E$2:$E$201,MATCH(K2,$A$2:$A$201,0))),K2)&"/","")&IF(J2<>"",IFERROR(IF(INDEX($E$2:$E$201,MATCH(J2,$A$2:$A$201,0))="",J2,INDEX($E$2:$E$201,MATCH(J2,$A$2:$A$201,0))),J2)&"/","")&IF(I2<>"",IFERROR(IF(INDEX($E$2:$E$201,MATCH(I2,$A$2:$A$201,0))="",I2,INDEX($E$2:$E$201,MATCH(I2,$A$2:$A$201,0))),I2)&"/","")&IF(H2<>"",IFERROR(IF(INDEX($E$2:$E$201,MATCH(H2,$A$2:$A$201,0))="",H2,INDEX($E$2:$E$201,MATCH(H2,$A$2:$A$201,0))),H2)&"/","")&IF(E2="",A2,E2)) | G2: =IF(A2="","",IF(SUMPRODUCT(--EXACT($A$2:$A$201,A2))>1,"Duplicate ID",IF(SUMPRODUCT(--EXACT('1 Types'!$A$2:$A$201,C2))=0,"Type is not on the Types sheet",IF(AND(D2<>"",NOT(SUMPRODUCT(--EXACT($A$2:$A$201,D2))>0)),"Parent is not an asset",IF(AND(D2="",IFERROR(INDEX('1 Types'!$E$2:$E$201,MATCH(C2,'1 Types'!$A$2:$A$201,0)),"")<>"yes"),"Needs a parent",IF(OR(L2<>"",H2=A2,I2=A2,J2=A2,K2=A2),"Parent loop, or more than five levels","ok")))))) | H2: =IF(A2="","",D2) | I2: =IF(H2="","",IFERROR(INDEX($D$2:$D$201,MATCH(H2,$A$2:$A$201,0)),"")) | J2: =IF(I2="","",IFERROR(INDEX($D$2:$D$201,MATCH(I2,$A$2:$A$201,0)),"")) | K2: =IF(J2="","",IFERROR(INDEX($D$2:$D$201,MATCH(J2,$A$2:$A$201,0)),"")) | L2: =IF(K2="","",IFERROR(INDEX($D$2:$D$201,MATCH(K2,$A$2:$A$201,0)),"")) | M2: =IF(A2="","",IF(K2<>"",K2,IF(J2<>"",J2,IF(I2<>"",I2,IF(H2<>"",H2,A2)))))
F3: =IF(A3="","",IF(K3<>"",IFERROR(IF(INDEX($E$2:$E$201,MATCH(K3,$A$2:$A$201,0))="",K3,INDEX($E$2:$E$201,MATCH(K3,$A$2:$A$201,0))),K3)&"/","")&IF(J3<>"",IFERROR(IF(INDEX($E$2:$E$201,MATCH(J3,$A$2:$A$201,0))="",J3,INDEX($E$2:$E$201,MATCH(J3,$A$2:$A$201,0))),J3)&"/","")&IF(I3<>"",IFERROR(IF(INDEX($E$2:$E$201,MATCH(I3,$A$2:$A$201,0))="",I3,INDEX($E$2:$E$201,MATCH(I3,$A$2:$A$201,0))),I3)&"/","")&IF(H3<>"",IFERROR(IF(INDEX($E$2:$E$201,MATCH(H3,$A$2:$A$201,0))="",H3,INDEX($E$2:$E$201,MATCH(H3,$A$2:$A$201,0))),H3)&"/","")&IF(E3="",A3,E3)) | G3: =IF(A3="","",IF(SUMPRODUCT(--EXACT($A$2:$A$201,A3))>1,"Duplicate ID",IF(SUMPRODUCT(--EXACT('1 Types'!$A$2:$A$201,C3))=0,"Type is not on the Types sheet",IF(AND(D3<>"",NOT(SUMPRODUCT(--EXACT($A$2:$A$201,D3))>0)),"Parent is not an asset",IF(AND(D3="",IFERROR(INDEX('1 Types'!$E$2:$E$201,MATCH(C3,'1 Types'!$A$2:$A$201,0)),"")<>"yes"),"Needs a parent",IF(OR(L3<>"",H3=A3,I3=A3,J3=A3,K3=A3),"Parent loop, or more than five levels","ok")))))) | H3: =IF(A3="","",D3) | I3: =IF(H3="","",IFERROR(INDEX($D$2:$D$201,MATCH(H3,$A$2:$A$201,0)),"")) | J3: =IF(I3="","",IFERROR(INDEX($D$2:$D$201,MATCH(I3,$A$2:$A$201,0)),"")) | K3: =IF(J3="","",IFERROR(INDEX($D$2:$D$201,MATCH(J3,$A$2:$A$201,0)),"")) | L3: =IF(K3="","",IFERROR(INDEX($D$2:$D$201,MATCH(K3,$A$2:$A$201,0)),"")) | M3: =IF(A3="","",IF(K3<>"",K3,IF(J3<>"",J3,IF(I3<>"",I3,IF(H3<>"",H3,A3)))))
F4: =IF(A4="","",IF(K4<>"",IFERROR(IF(INDEX($E$2:$E$201,MATCH(K4,$A$2:$A$201,0))="",K4,INDEX($E$2:$E$201,MATCH(K4,$A$2:$A$201,0))),K4)&"/","")&IF(J4<>"",IFERROR(IF(INDEX($E$2:$E$201,MATCH(J4,$A$2:$A$201,0))="",J4,INDEX($E$2:$E$201,MATCH(J4,$A$2:$A$201,0))),J4)&"/","")&IF(I4<>"",IFERROR(IF(INDEX($E$2:$E$201,MATCH(I4,$A$2:$A$201,0))="",I4,INDEX($E$2:$E$201,MATCH(I4,$A$2:$A$201,0))),I4)&"/","")&IF(H4<>"",IFERROR(IF(INDEX($E$2:$E$201,MATCH(H4,$A$2:$A$201,0))="",H4,INDEX($E$2:$E$201,MATCH(H4,$A$2:$A$201,0))),H4)&"/","")&IF(E4="",A4,E4)) | G4: =IF(A4="","",IF(SUMPRODUCT(--EXACT($A$2:$A$201,A4))>1,"Duplicate ID",IF(SUMPRODUCT(--EXACT('1 Types'!$A$2:$A$201,C4))=0,"Type is not on the Types sheet",IF(AND(D4<>"",NOT(SUMPRODUCT(--EXACT($A$2:$A$201,D4))>0)),"Parent is not an asset",IF(AND(D4="",IFERROR(INDEX('1 Types'!$E$2:$E$201,MATCH(C4,'1 Types'!$A$2:$A$201,0)),"")<>"yes"),"Needs a parent",IF(OR(L4<>"",H4=A4,I4=A4,J4=A4,K4=A4),"Parent loop, or more than five levels","ok")))))) | H4: =IF(A4="","",D4) | I4: =IF(H4="","",IFERROR(INDEX($D$2:$D$201,MATCH(H4,$A$2:$A$201,0)),"")) | J4: =IF(I4="","",IFERROR(INDEX($D$2:$D$201,MATCH(I4,$A$2:$A$201,0)),"")) | K4: =IF(J4="","",IFERROR(INDEX($D$2:$D$201,MATCH(J4,$A$2:$A$201,0)),"")) | L4: =IF(K4="","",IFERROR(INDEX($D$2:$D$201,MATCH(K4,$A$2:$A$201,0)),"")) | M4: =IF(A4="","",IF(K4<>"",K4,IF(J4<>"",J4,IF(I4<>"",I4,IF(H4<>"",H4,A4)))))
F5: =IF(A5="","",IF(K5<>"",IFERROR(IF(INDEX($E$2:$E$201,MATCH(K5,$A$2:$A$201,0))="",K5,INDEX($E$2:$E$201,MATCH(K5,$A$2:$A$201,0))),K5)&"/","")&IF(J5<>"",IFERROR(IF(INDEX($E$2:$E$201,MATCH(J5,$A$2:$A$201,0))="",J5,INDEX($E$2:$E$201,MATCH(J5,$A$2:$A$201,0))),J5)&"/","")&IF(I5<>"",IFERROR(IF(INDEX($E$2:$E$201,MATCH(I5,$A$2:$A$201,0))="",I5,INDEX($E$2:$E$201,MATCH(I5,$A$2:$A$201,0))),I5)&"/","")&IF(H5<>"",IFERROR(IF(INDEX($E$2:$E$201,MATCH(H5,$A$2:$A$201,0))="",H5,INDEX($E$2:$E$201,MATCH(H5,$A$2:$A$201,0))),H5)&"/","")&IF(E5="",A5,E5)) | G5: =IF(A5="","",IF(SUMPRODUCT(--EXACT($A$2:$A$201,A5))>1,"Duplicate ID",IF(SUMPRODUCT(--EXACT('1 Types'!$A$2:$A$201,C5))=0,"Type is not on the Types sheet",IF(AND(D5<>"",NOT(SUMPRODUCT(--EXACT($A$2:$A$201,D5))>0)),"Parent is not an asset",IF(AND(D5="",IFERROR(INDEX('1 Types'!$E$2:$E$201,MATCH(C5,'1 Types'!$A$2:$A$201,0)),"")<>"yes"),"Needs a parent",IF(OR(L5<>"",H5=A5,I5=A5,J5=A5,K5=A5),"Parent loop, or more than five levels","ok")))))) | H5: =IF(A5="","",D5) | I5: =IF(H5="","",IFERROR(INDEX($D$2:$D$201,MATCH(H5,$A$2:$A$201,0)),"")) | J5: =IF(I5="","",IFERROR(INDEX($D$2:$D$201,MATCH(I5,$A$2:$A$201,0)),"")) | K5: =IF(J5="","",IFERROR(INDEX($D$2:$D$201,MATCH(J5,$A$2:$A$201,0)),"")) | L5: =IF(K5="","",IFERROR(INDEX($D$2:$D$201,MATCH(K5,$A$2:$A$201,0)),"")) | M5: =IF(A5="","",IF(K5<>"",K5,IF(J5<>"",J5,IF(I5<>"",I5,IF(H5<>"",H5,A5)))))
F6: =IF(A6="","",IF(K6<>"",IFERROR(IF(INDEX($E$2:$E$201,MATCH(K6,$A$2:$A$201,0))="",K6,INDEX($E$2:$E$201,MATCH(K6,$A$2:$A$201,0))),K6)&"/","")&IF(J6<>"",IFERROR(IF(INDEX($E$2:$E$201,MATCH(J6,$A$2:$A$201,0))="",J6,INDEX($E$2:$E$201,MATCH(J6,$A$2:$A$201,0))),J6)&"/","")&IF(I6<>"",IFERROR(IF(INDEX($E$2:$E$201,MATCH(I6,$A$2:$A$201,0))="",I6,INDEX($E$2:$E$201,MATCH(I6,$A$2:$A$201,0))),I6)&"/","")&IF(H6<>"",IFERROR(IF(INDEX($E$2:$E$201,MATCH(H6,$A$2:$A$201,0))="",H6,INDEX($E$2:$E$201,MATCH(H6,$A$2:$A$201,0))),H6)&"/","")&IF(E6="",A6,E6)) | G6: =IF(A6="","",IF(SUMPRODUCT(--EXACT($A$2:$A$201,A6))>1,"Duplicate ID",IF(SUMPRODUCT(--EXACT('1 Types'!$A$2:$A$201,C6))=0,"Type is not on the Types sheet",IF(AND(D6<>"",NOT(SUMPRODUCT(--EXACT($A$2:$A$201,D6))>0)),"Parent is not an asset",IF(AND(D6="",IFERROR(INDEX('1 Types'!$E$2:$E$201,MATCH(C6,'1 Types'!$A$2:$A$201,0)),"")<>"yes"),"Needs a parent",IF(OR(L6<>"",H6=A6,I6=A6,J6=A6,K6=A6),"Parent loop, or more than five levels","ok")))))) | H6: =IF(A6="","",D6) | I6: =IF(H6="","",IFERROR(INDEX($D$2:$D$201,MATCH(H6,$A$2:$A$201,0)),"")) | J6: =IF(I6="","",IFERROR(INDEX($D$2:$D$201,MATCH(I6,$A$2:$A$201,0)),"")) | K6: =IF(J6="","",IFERROR(INDEX($D$2:$D$201,MATCH(J6,$A$2:$A$201,0)),"")) | L6: =IF(K6="","",IFERROR(INDEX($D$2:$D$201,MATCH(K6,$A$2:$A$201,0)),"")) | M6: =IF(A6="","",IF(K6<>"",K6,IF(J6<>"",J6,IF(I6<>"",I6,IF(H6<>"",H6,A6)))))
F7: =IF(A7="","",IF(K7<>"",IFERROR(IF(INDEX($E$2:$E$201,MATCH(K7,$A$2:$A$201,0))="",K7,INDEX($E$2:$E$201,MATCH(K7,$A$2:$A$201,0))),K7)&"/","")&IF(J7<>"",IFERROR(IF(INDEX($E$2:$E$201,MATCH(J7,$A$2:$A$201,0))="",J7,INDEX($E$2:$E$201,MATCH(J7,$A$2:$A$201,0))),J7)&"/","")&IF(I7<>"",IFERROR(IF(INDEX($E$2:$E$201,MATCH(I7,$A$2:$A$201,0))="",I7,INDEX($E$2:$E$201,MATCH(I7,$A$2:$A$201,0))),I7)&"/","")&IF(H7<>"",IFERROR(IF(INDEX($E$2:$E$201,MATCH(H7,$A$2:$A$201,0))="",H7,INDEX($E$2:$E$201,MATCH(H7,$A$2:$A$201,0))),H7)&"/","")&IF(E7="",A7,E7)) | G7: =IF(A7="","",IF(SUMPRODUCT(--EXACT($A$2:$A$201,A7))>1,"Duplicate ID",IF(SUMPRODUCT(--EXACT('1 Types'!$A$2:$A$201,C7))=0,"Type is not on the Types sheet",IF(AND(D7<>"",NOT(SUMPRODUCT(--EXACT($A$2:$A$201,D7))>0)),"Parent is not an asset",IF(AND(D7="",IFERROR(INDEX('1 Types'!$E$2:$E$201,MATCH(C7,'1 Types'!$A$2:$A$201,0)),"")<>"yes"),"Needs a parent",IF(OR(L7<>"",H7=A7,I7=A7,J7=A7,K7=A7),"Parent loop, or more than five levels","ok")))))) | H7: =IF(A7="","",D7) | I7: =IF(H7="","",IFERROR(INDEX($D$2:$D$201,MATCH(H7,$A$2:$A$201,0)),"")) | J7: =IF(I7="","",IFERROR(INDEX($D$2:$D$201,MATCH(I7,$A$2:$A$201,0)),"")) | K7: =IF(J7="","",IFERROR(INDEX($D$2:$D$201,MATCH(J7,$A$2:$A$201,0)),"")) | L7: =IF(K7="","",IFERROR(INDEX($D$2:$D$201,MATCH(K7,$A$2:$A$201,0)),"")) | M7: =IF(A7="","",IF(K7<>"",K7,IF(J7<>"",J7,IF(I7<>"",I7,IF(H7<>"",H7,A7)))))
F8: =IF(A8="","",IF(K8<>"",IFERROR(IF(INDEX($E$2:$E$201,MATCH(K8,$A$2:$A$201,0))="",K8,INDEX($E$2:$E$201,MATCH(K8,$A$2:$A$201,0))),K8)&"/","")&IF(J8<>"",IFERROR(IF(INDEX($E$2:$E$201,MATCH(J8,$A$2:$A$201,0))="",J8,INDEX($E$2:$E$201,MATCH(J8,$A$2:$A$201,0))),J8)&"/","")&IF(I8<>"",IFERROR(IF(INDEX($E$2:$E$201,MATCH(I8,$A$2:$A$201,0))="",I8,INDEX($E$2:$E$201,MATCH(I8,$A$2:$A$201,0))),I8)&"/","")&IF(H8<>"",IFERROR(IF(INDEX($E$2:$E$201,MATCH(H8,$A$2:$A$201,0))="",H8,INDEX($E$2:$E$201,MATCH(H8,$A$2:$A$201,0))),H8)&"/","")&IF(E8="",A8,E8)) | G8: =IF(A8="","",IF(SUMPRODUCT(--EXACT($A$2:$A$201,A8))>1,"Duplicate ID",IF(SUMPRODUCT(--EXACT('1 Types'!$A$2:$A$201,C8))=0,"Type is not on the Types sheet",IF(AND(D8<>"",NOT(SUMPRODUCT(--EXACT($A$2:$A$201,D8))>0)),"Parent is not an asset",IF(AND(D8="",IFERROR(INDEX('1 Types'!$E$2:$E$201,MATCH(C8,'1 Types'!$A$2:$A$201,0)),"")<>"yes"),"Needs a parent",IF(OR(L8<>"",H8=A8,I8=A8,J8=A8,K8=A8),"Parent loop, or more than five levels","ok")))))) | H8: =IF(A8="","",D8) | I8: =IF(H8="","",IFERROR(INDEX($D$2:$D$201,MATCH(H8,$A$2:$A$201,0)),"")) | J8: =IF(I8="","",IFERROR(INDEX($D$2:$D$201,MATCH(I8,$A$2:$A$201,0)),"")) | K8: =IF(J8="","",IFERROR(INDEX($D$2:$D$201,MATCH(J8,$A$2:$A$201,0)),"")) | L8: =IF(K8="","",IFERROR(INDEX($D$2:$D$201,MATCH(K8,$A$2:$A$201,0)),"")) | M8: =IF(A8="","",IF(K8<>"",K8,IF(J8<>"",J8,IF(I8<>"",I8,IF(H8<>"",H8,A8)))))
F9: =IF(A9="","",IF(K9<>"",IFERROR(IF(INDEX($E$2:$E$201,MATCH(K9,$A$2:$A$201,0))="",K9,INDEX($E$2:$E$201,MATCH(K9,$A$2:$A$201,0))),K9)&"/","")&IF(J9<>"",IFERROR(IF(INDEX($E$2:$E$201,MATCH(J9,$A$2:$A$201,0))="",J9,INDEX($E$2:$E$201,MATCH(J9,$A$2:$A$201,0))),J9)&"/","")&IF(I9<>"",IFERROR(IF(INDEX($E$2:$E$201,MATCH(I9,$A$2:$A$201,0))="",I9,INDEX($E$2:$E$201,MATCH(I9,$A$2:$A$201,0))),I9)&"/","")&IF(H9<>"",IFERROR(IF(INDEX($E$2:$E$201,MATCH(H9,$A$2:$A$201,0))="",H9,INDEX($E$2:$E$201,MATCH(H9,$A$2:$A$201,0))),H9)&"/","")&IF(E9="",A9,E9)) | G9: =IF(A9="","",IF(SUMPRODUCT(--EXACT($A$2:$A$201,A9))>1,"Duplicate ID",IF(SUMPRODUCT(--EXACT('1 Types'!$A$2:$A$201,C9))=0,"Type is not on the Types sheet",IF(AND(D9<>"",NOT(SUMPRODUCT(--EXACT($A$2:$A$201,D9))>0)),"Parent is not an asset",IF(AND(D9="",IFERROR(INDEX('1 Types'!$E$2:$E$201,MATCH(C9,'1 Types'!$A$2:$A$201,0)),"")<>"yes"),"Needs a parent",IF(OR(L9<>"",H9=A9,I9=A9,J9=A9,K9=A9),"Parent loop, or more than five levels","ok")))))) | H9: =IF(A9="","",D9) | I9: =IF(H9="","",IFERROR(INDEX($D$2:$D$201,MATCH(H9,$A$2:$A$201,0)),"")) | J9: =IF(I9="","",IFERROR(INDEX($D$2:$D$201,MATCH(I9,$A$2:$A$201,0)),"")) | K9: =IF(J9="","",IFERROR(INDEX($D$2:$D$201,MATCH(J9,$A$2:$A$201,0)),"")) | L9: =IF(K9="","",IFERROR(INDEX($D$2:$D$201,MATCH(K9,$A$2:$A$201,0)),"")) | M9: =IF(A9="","",IF(K9<>"",K9,IF(J9<>"",J9,IF(I9<>"",I9,IF(H9<>"",H9,A9)))))
F10: =IF(A10="","",IF(K10<>"",IFERROR(IF(INDEX($E$2:$E$201,MATCH(K10,$A$2:$A$201,0))="",K10,INDEX($E$2:$E$201,MATCH(K10,$A$2:$A$201,0))),K10)&"/","")&IF(J10<>"",IFERROR(IF(INDEX($E$2:$E$201,MATCH(J10,$A$2:$A$201,0))="",J10,INDEX($E$2:$E$201,MATCH(J10,$A$2:$A$201,0))),J10)&"/","")&IF(I10<>"",IFERROR(IF(INDEX($E$2:$E$201,MATCH(I10,$A$2:$A$201,0))="",I10,INDEX($E$2:$E$201,MATCH(I10,$A$2:$A$201,0))),I10)&"/","")&IF(H10<>"",IFERROR(IF(INDEX($E$2:$E$201,MATCH(H10,$A$2:$A$201,0))="",H10,INDEX($E$2:$E$201,MATCH(H10,$A$2:$A$201,0))),H10)&"/","")&IF(E10="",A10,E10)) | G10: =IF(A10="","",IF(SUMPRODUCT(--EXACT($A$2:$A$201,A10))>1,"Duplicate ID",IF(SUMPRODUCT(--EXACT('1 Types'!$A$2:$A$201,C10))=0,"Type is not on the Types sheet",IF(AND(D10<>"",NOT(SUMPRODUCT(--EXACT($A$2:$A$201,D10))>0)),"Parent is not an asset",IF(AND(D10="",IFERROR(INDEX('1 Types'!$E$2:$E$201,MATCH(C10,'1 Types'!$A$2:$A$201,0)),"")<>"yes"),"Needs a parent",IF(OR(L10<>"",H10=A10,I10=A10,J10=A10,K10=A10),"Parent loop, or more than five levels","ok")))))) | H10: =IF(A10="","",D10) | I10: =IF(H10="","",IFERROR(INDEX($D$2:$D$201,MATCH(H10,$A$2:$A$201,0)),"")) | J10: =IF(I10="","",IFERROR(INDEX($D$2:$D$201,MATCH(I10,$A$2:$A$201,0)),"")) | K10: =IF(J10="","",IFERROR(INDEX($D$2:$D$201,MATCH(J10,$A$2:$A$201,0)),"")) | L10: =IF(K10="","",IFERROR(INDEX($D$2:$D$201,MATCH(K10,$A$2:$A$201,0)),"")) | M10: =IF(A10="","",IF(K10<>"",K10,IF(J10<>"",J10,IF(I10<>"",I10,IF(H10<>"",H10,A10)))))
F11: =IF(A11="","",IF(K11<>"",IFERROR(IF(INDEX($E$2:$E$201,MATCH(K11,$A$2:$A$201,0))="",K11,INDEX($E$2:$E$201,MATCH(K11,$A$2:$A$201,0))),K11)&"/","")&IF(J11<>"",IFERROR(IF(INDEX($E$2:$E$201,MATCH(J11,$A$2:$A$201,0))="",J11,INDEX($E$2:$E$201,MATCH(J11,$A$2:$A$201,0))),J11)&"/","")&IF(I11<>"",IFERROR(IF(INDEX($E$2:$E$201,MATCH(I11,$A$2:$A$201,0))="",I11,INDEX($E$2:$E$201,MATCH(I11,$A$2:$A$201,0))),I11)&"/","")&IF(H11<>"",IFERROR(IF(INDEX($E$2:$E$201,MATCH(H11,$A$2:$A$201,0))="",H11,INDEX($E$2:$E$201,MATCH(H11,$A$2:$A$201,0))),H11)&"/","")&IF(E11="",A11,E11)) | G11: =IF(A11="","",IF(SUMPRODUCT(--EXACT($A$2:$A$201,A11))>1,"Duplicate ID",IF(SUMPRODUCT(--EXACT('1 Types'!$A$2:$A$201,C11))=0,"Type is not on the Types sheet",IF(AND(D11<>"",NOT(SUMPRODUCT(--EXACT($A$2:$A$201,D11))>0)),"Parent is not an asset",IF(AND(D11="",IFERROR(INDEX('1 Types'!$E$2:$E$201,MATCH(C11,'1 Types'!$A$2:$A$201,0)),"")<>"yes"),"Needs a parent",IF(OR(L11<>"",H11=A11,I11=A11,J11=A11,K11=A11),"Parent loop, or more than five levels","ok")))))) | H11: =IF(A11="","",D11) | I11: =IF(H11="","",IFERROR(INDEX($D$2:$D$201,MATCH(H11,$A$2:$A$201,0)),"")) | J11: =IF(I11="","",IFERROR(INDEX($D$2:$D$201,MATCH(I11,$A$2:$A$201,0)),"")) | K11: =IF(J11="","",IFERROR(INDEX($D$2:$D$201,MATCH(J11,$A$2:$A$201,0)),"")) | L11: =IF(K11="","",IFERROR(INDEX($D$2:$D$201,MATCH(K11,$A$2:$A$201,0)),"")) | M11: =IF(A11="","",IF(K11<>"",K11,IF(J11<>"",J11,IF(I11<>"",I11,IF(H11<>"",H11,A11)))))
F12: =IF(A12="","",IF(K12<>"",IFERROR(IF(INDEX($E$2:$E$201,MATCH(K12,$A$2:$A$201,0))="",K12,INDEX($E$2:$E$201,MATCH(K12,$A$2:$A$201,0))),K12)&"/","")&IF(J12<>"",IFERROR(IF(INDEX($E$2:$E$201,MATCH(J12,$A$2:$A$201,0))="",J12,INDEX($E$2:$E$201,MATCH(J12,$A$2:$A$201,0))),J12)&"/","")&IF(I12<>"",IFERROR(IF(INDEX($E$2:$E$201,MATCH(I12,$A$2:$A$201,0))="",I12,INDEX($E$2:$E$201,MATCH(I12,$A$2:$A$201,0))),I12)&"/","")&IF(H12<>"",IFERROR(IF(INDEX($E$2:$E$201,MATCH(H12,$A$2:$A$201,0))="",H12,INDEX($E$2:$E$201,MATCH(H12,$A$2:$A$201,0))),H12)&"/","")&IF(E12="",A12,E12)) | G12: =IF(A12="","",IF(SUMPRODUCT(--EXACT($A$2:$A$201,A12))>1,"Duplicate ID",IF(SUMPRODUCT(--EXACT('1 Types'!$A$2:$A$201,C12))=0,"Type is not on the Types sheet",IF(AND(D12<>"",NOT(SUMPRODUCT(--EXACT($A$2:$A$201,D12))>0)),"Parent is not an asset",IF(AND(D12="",IFERROR(INDEX('1 Types'!$E$2:$E$201,MATCH(C12,'1 Types'!$A$2:$A$201,0)),"")<>"yes"),"Needs a parent",IF(OR(L12<>"",H12=A12,I12=A12,J12=A12,K12=A12),"Parent loop, or more than five levels","ok")))))) | H12: =IF(A12="","",D12) | I12: =IF(H12="","",IFERROR(INDEX($D$2:$D$201,MATCH(H12,$A$2:$A$201,0)),"")) | J12: =IF(I12="","",IFERROR(INDEX($D$2:$D$201,MATCH(I12,$A$2:$A$201,0)),"")) | K12: =IF(J12="","",IFERROR(INDEX($D$2:$D$201,MATCH(J12,$A$2:$A$201,0)),"")) | L12: =IF(K12="","",IFERROR(INDEX($D$2:$D$201,MATCH(K12,$A$2:$A$201,0)),"")) | M12: =IF(A12="","",IF(K12<>"",K12,IF(J12<>"",J12,IF(I12<>"",I12,IF(H12<>"",H12,A12)))))
F13: =IF(A13="","",IF(K13<>"",IFERROR(IF(INDEX($E$2:$E$201,MATCH(K13,$A$2:$A$201,0))="",K13,INDEX($E$2:$E$201,MATCH(K13,$A$2:$A$201,0))),K13)&"/","")&IF(J13<>"",IFERROR(IF(INDEX($E$2:$E$201,MATCH(J13,$A$2:$A$201,0))="",J13,INDEX($E$2:$E$201,MATCH(J13,$A$2:$A$201,0))),J13)&"/","")&IF(I13<>"",IFERROR(IF(INDEX($E$2:$E$201,MATCH(I13,$A$2:$A$201,0))="",I13,INDEX($E$2:$E$201,MATCH(I13,$A$2:$A$201,0))),I13)&"/","")&IF(H13<>"",IFERROR(IF(INDEX($E$2:$E$201,MATCH(H13,$A$2:$A$201,0))="",H13,INDEX($E$2:$E$201,MATCH(H13,$A$2:$A$201,0))),H13)&"/","")&IF(E13="",A13,E13)) | G13: =IF(A13="","",IF(SUMPRODUCT(--EXACT($A$2:$A$201,A13))>1,"Duplicate ID",IF(SUMPRODUCT(--EXACT('1 Types'!$A$2:$A$201,C13))=0,"Type is not on the Types sheet",IF(AND(D13<>"",NOT(SUMPRODUCT(--EXACT($A$2:$A$201,D13))>0)),"Parent is not an asset",IF(AND(D13="",IFERROR(INDEX('1 Types'!$E$2:$E$201,MATCH(C13,'1 Types'!$A$2:$A$201,0)),"")<>"yes"),"Needs a parent",IF(OR(L13<>"",H13=A13,I13=A13,J13=A13,K13=A13),"Parent loop, or more than five levels","ok")))))) | H13: =IF(A13="","",D13) | I13: =IF(H13="","",IFERROR(INDEX($D$2:$D$201,MATCH(H13,$A$2:$A$201,0)),"")) | J13: =IF(I13="","",IFERROR(INDEX($D$2:$D$201,MATCH(I13,$A$2:$A$201,0)),"")) | K13: =IF(J13="","",IFERROR(INDEX($D$2:$D$201,MATCH(J13,$A$2:$A$201,0)),"")) | L13: =IF(K13="","",IFERROR(INDEX($D$2:$D$201,MATCH(K13,$A$2:$A$201,0)),"")) | M13: =IF(A13="","",IF(K13<>"",K13,IF(J13<>"",J13,IF(I13<>"",I13,IF(H13<>"",H13,A13)))))
... F201: =IF(A201="","",IF(K201<>"",IFERROR(IF(INDEX($E$2:$E$201,MATCH(K201,$A$2:$A$201,0))="",K201,INDEX($E$2:$E$201,MATCH(K201,$A$2:$A$201,0))),K201)&"/","")&IF(J201<>"",IFERROR(IF(INDEX($E$2:$E$201,MATCH(J201,$A$2:$A$201,0))="",J201,INDEX($E$2:$E$201,MATCH(J201,$A$2:$A$201,0))),J201)&"/","")&IF(I201<>"",IFERROR(IF(INDEX($E$2:$E$201,MATCH(I201,$A$2:$A$201,0))="",I201,INDEX($E$2:$E$201,MATCH(I201,$A$2:$A$201,0))),I201)&"/","")&IF(H201<>"",IFERROR(IF(INDEX($E$2:$E$201,MATCH(H201,$A$2:$A$201,0))="",H201,INDEX($E$2:$E$201,MATCH(H201,$A$2:$A$201,0))),H201)&"/","")&IF(E201="",A201,E201)) | G201: =IF(A201="","",IF(SUMPRODUCT(--EXACT($A$2:$A$201,A201))>1,"Duplicate ID",IF(SUMPRODUCT(--EXACT('1 Types'!$A$2:$A$201,C201))=0,"Type is not on the Types sheet",IF(AND(D201<>"",NOT(SUMPRODUCT(--EXACT($A$2:$A$201,D201))>0)),"Parent is not an asset",IF(AND(D201="",IFERROR(INDEX('1 Types'!$E$2:$E$201,MATCH(C201,'1 Types'!$A$2:$A$201,0)),"")<>"yes"),"Needs a parent",IF(OR(L201<>"",H201=A201,I201=A201,J201=A201,K201=A201),"Parent loop, or more than five levels","ok")))))) | H201: =IF(A201="","",D201) | I201: =IF(H201="","",IFERROR(INDEX($D$2:$D$201,MATCH(H201,$A$2:$A$201,0)),"")) | J201: =IF(I201="","",IFERROR(INDEX($D$2:$D$201,MATCH(I201,$A$2:$A$201,0)),"")) | K201: =IF(J201="","",IFERROR(INDEX($D$2:$D$201,MATCH(J201,$A$2:$A$201,0)),"")) | L201: =IF(K201="","",IFERROR(INDEX($D$2:$D$201,MATCH(K201,$A$2:$A$201,0)),"")) | M201: =IF(A201="","",IF(K201<>"",K201,IF(J201<>"",J201,IF(I201<>"",I201,IF(H201<>"",H201,A201)))))

Sheet 2 Measurements
A1: Measurement ID | B1: Kind | C1: Asset it belongs to | D1: What it measures (from the Measurement types sheet) | E1: Unit (blank for a state or alarm) | F1: Short name (last part of the topic) | G1: Display name | H1: On the Bindings sheet? (do not edit) | I1: Check (do not edit)
H2: =IF(A2="","",IF(SUMPRODUCT(--EXACT('3 Bindings'!$A$2:$A$201,A2))>0,"yes","not yet")) | I2: =IF(A2="","",IF(SUMPRODUCT(--EXACT($A$2:$A$201,A2))>1,"Duplicate ID",IF(AND(B2<>"Measurement",B2<>"State or alarm"),"Kind must be Measurement or State or alarm",IF(SUMPRODUCT(--EXACT('2 Assets'!$A$2:$A$201,C2))=0,"Asset is not on the Assets sheet",IF(SUMPRODUCT(--EXACT('1 Measurement types'!$A$2:$A$201,D2))=0,"Not on the Measurement types sheet",IF(INDEX('1 Measurement types'!$B$2:$B$201,MATCH(D2,'1 Measurement types'!$A$2:$A$201,0))<>B2,"Kind does not match its measurement type",IF(AND(B2="Measurement",E2=""),"A measurement needs a unit",IF(AND(B2="Measurement",NOT(EXACT(E2,INDEX('1 Measurement types'!$C$2:$C$201,MATCH(D2,'1 Measurement types'!$A$2:$A$201,0))))),"Unit does not match its measurement type",IF(F2="","Give it a short name","ok")))))))))
H3: =IF(A3="","",IF(SUMPRODUCT(--EXACT('3 Bindings'!$A$2:$A$201,A3))>0,"yes","not yet")) | I3: =IF(A3="","",IF(SUMPRODUCT(--EXACT($A$2:$A$201,A3))>1,"Duplicate ID",IF(AND(B3<>"Measurement",B3<>"State or alarm"),"Kind must be Measurement or State or alarm",IF(SUMPRODUCT(--EXACT('2 Assets'!$A$2:$A$201,C3))=0,"Asset is not on the Assets sheet",IF(SUMPRODUCT(--EXACT('1 Measurement types'!$A$2:$A$201,D3))=0,"Not on the Measurement types sheet",IF(INDEX('1 Measurement types'!$B$2:$B$201,MATCH(D3,'1 Measurement types'!$A$2:$A$201,0))<>B3,"Kind does not match its measurement type",IF(AND(B3="Measurement",E3=""),"A measurement needs a unit",IF(AND(B3="Measurement",NOT(EXACT(E3,INDEX('1 Measurement types'!$C$2:$C$201,MATCH(D3,'1 Measurement types'!$A$2:$A$201,0))))),"Unit does not match its measurement type",IF(F3="","Give it a short name","ok")))))))))
H4: =IF(A4="","",IF(SUMPRODUCT(--EXACT('3 Bindings'!$A$2:$A$201,A4))>0,"yes","not yet")) | I4: =IF(A4="","",IF(SUMPRODUCT(--EXACT($A$2:$A$201,A4))>1,"Duplicate ID",IF(AND(B4<>"Measurement",B4<>"State or alarm"),"Kind must be Measurement or State or alarm",IF(SUMPRODUCT(--EXACT('2 Assets'!$A$2:$A$201,C4))=0,"Asset is not on the Assets sheet",IF(SUMPRODUCT(--EXACT('1 Measurement types'!$A$2:$A$201,D4))=0,"Not on the Measurement types sheet",IF(INDEX('1 Measurement types'!$B$2:$B$201,MATCH(D4,'1 Measurement types'!$A$2:$A$201,0))<>B4,"Kind does not match its measurement type",IF(AND(B4="Measurement",E4=""),"A measurement needs a unit",IF(AND(B4="Measurement",NOT(EXACT(E4,INDEX('1 Measurement types'!$C$2:$C$201,MATCH(D4,'1 Measurement types'!$A$2:$A$201,0))))),"Unit does not match its measurement type",IF(F4="","Give it a short name","ok")))))))))
H5: =IF(A5="","",IF(SUMPRODUCT(--EXACT('3 Bindings'!$A$2:$A$201,A5))>0,"yes","not yet")) | I5: =IF(A5="","",IF(SUMPRODUCT(--EXACT($A$2:$A$201,A5))>1,"Duplicate ID",IF(AND(B5<>"Measurement",B5<>"State or alarm"),"Kind must be Measurement or State or alarm",IF(SUMPRODUCT(--EXACT('2 Assets'!$A$2:$A$201,C5))=0,"Asset is not on the Assets sheet",IF(SUMPRODUCT(--EXACT('1 Measurement types'!$A$2:$A$201,D5))=0,"Not on the Measurement types sheet",IF(INDEX('1 Measurement types'!$B$2:$B$201,MATCH(D5,'1 Measurement types'!$A$2:$A$201,0))<>B5,"Kind does not match its measurement type",IF(AND(B5="Measurement",E5=""),"A measurement needs a unit",IF(AND(B5="Measurement",NOT(EXACT(E5,INDEX('1 Measurement types'!$C$2:$C$201,MATCH(D5,'1 Measurement types'!$A$2:$A$201,0))))),"Unit does not match its measurement type",IF(F5="","Give it a short name","ok")))))))))
H6: =IF(A6="","",IF(SUMPRODUCT(--EXACT('3 Bindings'!$A$2:$A$201,A6))>0,"yes","not yet")) | I6: =IF(A6="","",IF(SUMPRODUCT(--EXACT($A$2:$A$201,A6))>1,"Duplicate ID",IF(AND(B6<>"Measurement",B6<>"State or alarm"),"Kind must be Measurement or State or alarm",IF(SUMPRODUCT(--EXACT('2 Assets'!$A$2:$A$201,C6))=0,"Asset is not on the Assets sheet",IF(SUMPRODUCT(--EXACT('1 Measurement types'!$A$2:$A$201,D6))=0,"Not on the Measurement types sheet",IF(INDEX('1 Measurement types'!$B$2:$B$201,MATCH(D6,'1 Measurement types'!$A$2:$A$201,0))<>B6,"Kind does not match its measurement type",IF(AND(B6="Measurement",E6=""),"A measurement needs a unit",IF(AND(B6="Measurement",NOT(EXACT(E6,INDEX('1 Measurement types'!$C$2:$C$201,MATCH(D6,'1 Measurement types'!$A$2:$A$201,0))))),"Unit does not match its measurement type",IF(F6="","Give it a short name","ok")))))))))
H7: =IF(A7="","",IF(SUMPRODUCT(--EXACT('3 Bindings'!$A$2:$A$201,A7))>0,"yes","not yet")) | I7: =IF(A7="","",IF(SUMPRODUCT(--EXACT($A$2:$A$201,A7))>1,"Duplicate ID",IF(AND(B7<>"Measurement",B7<>"State or alarm"),"Kind must be Measurement or State or alarm",IF(SUMPRODUCT(--EXACT('2 Assets'!$A$2:$A$201,C7))=0,"Asset is not on the Assets sheet",IF(SUMPRODUCT(--EXACT('1 Measurement types'!$A$2:$A$201,D7))=0,"Not on the Measurement types sheet",IF(INDEX('1 Measurement types'!$B$2:$B$201,MATCH(D7,'1 Measurement types'!$A$2:$A$201,0))<>B7,"Kind does not match its measurement type",IF(AND(B7="Measurement",E7=""),"A measurement needs a unit",IF(AND(B7="Measurement",NOT(EXACT(E7,INDEX('1 Measurement types'!$C$2:$C$201,MATCH(D7,'1 Measurement types'!$A$2:$A$201,0))))),"Unit does not match its measurement type",IF(F7="","Give it a short name","ok")))))))))
H8: =IF(A8="","",IF(SUMPRODUCT(--EXACT('3 Bindings'!$A$2:$A$201,A8))>0,"yes","not yet")) | I8: =IF(A8="","",IF(SUMPRODUCT(--EXACT($A$2:$A$201,A8))>1,"Duplicate ID",IF(AND(B8<>"Measurement",B8<>"State or alarm"),"Kind must be Measurement or State or alarm",IF(SUMPRODUCT(--EXACT('2 Assets'!$A$2:$A$201,C8))=0,"Asset is not on the Assets sheet",IF(SUMPRODUCT(--EXACT('1 Measurement types'!$A$2:$A$201,D8))=0,"Not on the Measurement types sheet",IF(INDEX('1 Measurement types'!$B$2:$B$201,MATCH(D8,'1 Measurement types'!$A$2:$A$201,0))<>B8,"Kind does not match its measurement type",IF(AND(B8="Measurement",E8=""),"A measurement needs a unit",IF(AND(B8="Measurement",NOT(EXACT(E8,INDEX('1 Measurement types'!$C$2:$C$201,MATCH(D8,'1 Measurement types'!$A$2:$A$201,0))))),"Unit does not match its measurement type",IF(F8="","Give it a short name","ok")))))))))
H9: =IF(A9="","",IF(SUMPRODUCT(--EXACT('3 Bindings'!$A$2:$A$201,A9))>0,"yes","not yet")) | I9: =IF(A9="","",IF(SUMPRODUCT(--EXACT($A$2:$A$201,A9))>1,"Duplicate ID",IF(AND(B9<>"Measurement",B9<>"State or alarm"),"Kind must be Measurement or State or alarm",IF(SUMPRODUCT(--EXACT('2 Assets'!$A$2:$A$201,C9))=0,"Asset is not on the Assets sheet",IF(SUMPRODUCT(--EXACT('1 Measurement types'!$A$2:$A$201,D9))=0,"Not on the Measurement types sheet",IF(INDEX('1 Measurement types'!$B$2:$B$201,MATCH(D9,'1 Measurement types'!$A$2:$A$201,0))<>B9,"Kind does not match its measurement type",IF(AND(B9="Measurement",E9=""),"A measurement needs a unit",IF(AND(B9="Measurement",NOT(EXACT(E9,INDEX('1 Measurement types'!$C$2:$C$201,MATCH(D9,'1 Measurement types'!$A$2:$A$201,0))))),"Unit does not match its measurement type",IF(F9="","Give it a short name","ok")))))))))
H10: =IF(A10="","",IF(SUMPRODUCT(--EXACT('3 Bindings'!$A$2:$A$201,A10))>0,"yes","not yet")) | I10: =IF(A10="","",IF(SUMPRODUCT(--EXACT($A$2:$A$201,A10))>1,"Duplicate ID",IF(AND(B10<>"Measurement",B10<>"State or alarm"),"Kind must be Measurement or State or alarm",IF(SUMPRODUCT(--EXACT('2 Assets'!$A$2:$A$201,C10))=0,"Asset is not on the Assets sheet",IF(SUMPRODUCT(--EXACT('1 Measurement types'!$A$2:$A$201,D10))=0,"Not on the Measurement types sheet",IF(INDEX('1 Measurement types'!$B$2:$B$201,MATCH(D10,'1 Measurement types'!$A$2:$A$201,0))<>B10,"Kind does not match its measurement type",IF(AND(B10="Measurement",E10=""),"A measurement needs a unit",IF(AND(B10="Measurement",NOT(EXACT(E10,INDEX('1 Measurement types'!$C$2:$C$201,MATCH(D10,'1 Measurement types'!$A$2:$A$201,0))))),"Unit does not match its measurement type",IF(F10="","Give it a short name","ok")))))))))
H11: =IF(A11="","",IF(SUMPRODUCT(--EXACT('3 Bindings'!$A$2:$A$201,A11))>0,"yes","not yet")) | I11: =IF(A11="","",IF(SUMPRODUCT(--EXACT($A$2:$A$201,A11))>1,"Duplicate ID",IF(AND(B11<>"Measurement",B11<>"State or alarm"),"Kind must be Measurement or State or alarm",IF(SUMPRODUCT(--EXACT('2 Assets'!$A$2:$A$201,C11))=0,"Asset is not on the Assets sheet",IF(SUMPRODUCT(--EXACT('1 Measurement types'!$A$2:$A$201,D11))=0,"Not on the Measurement types sheet",IF(INDEX('1 Measurement types'!$B$2:$B$201,MATCH(D11,'1 Measurement types'!$A$2:$A$201,0))<>B11,"Kind does not match its measurement type",IF(AND(B11="Measurement",E11=""),"A measurement needs a unit",IF(AND(B11="Measurement",NOT(EXACT(E11,INDEX('1 Measurement types'!$C$2:$C$201,MATCH(D11,'1 Measurement types'!$A$2:$A$201,0))))),"Unit does not match its measurement type",IF(F11="","Give it a short name","ok")))))))))
H12: =IF(A12="","",IF(SUMPRODUCT(--EXACT('3 Bindings'!$A$2:$A$201,A12))>0,"yes","not yet")) | I12: =IF(A12="","",IF(SUMPRODUCT(--EXACT($A$2:$A$201,A12))>1,"Duplicate ID",IF(AND(B12<>"Measurement",B12<>"State or alarm"),"Kind must be Measurement or State or alarm",IF(SUMPRODUCT(--EXACT('2 Assets'!$A$2:$A$201,C12))=0,"Asset is not on the Assets sheet",IF(SUMPRODUCT(--EXACT('1 Measurement types'!$A$2:$A$201,D12))=0,"Not on the Measurement types sheet",IF(INDEX('1 Measurement types'!$B$2:$B$201,MATCH(D12,'1 Measurement types'!$A$2:$A$201,0))<>B12,"Kind does not match its measurement type",IF(AND(B12="Measurement",E12=""),"A measurement needs a unit",IF(AND(B12="Measurement",NOT(EXACT(E12,INDEX('1 Measurement types'!$C$2:$C$201,MATCH(D12,'1 Measurement types'!$A$2:$A$201,0))))),"Unit does not match its measurement type",IF(F12="","Give it a short name","ok")))))))))
H13: =IF(A13="","",IF(SUMPRODUCT(--EXACT('3 Bindings'!$A$2:$A$201,A13))>0,"yes","not yet")) | I13: =IF(A13="","",IF(SUMPRODUCT(--EXACT($A$2:$A$201,A13))>1,"Duplicate ID",IF(AND(B13<>"Measurement",B13<>"State or alarm"),"Kind must be Measurement or State or alarm",IF(SUMPRODUCT(--EXACT('2 Assets'!$A$2:$A$201,C13))=0,"Asset is not on the Assets sheet",IF(SUMPRODUCT(--EXACT('1 Measurement types'!$A$2:$A$201,D13))=0,"Not on the Measurement types sheet",IF(INDEX('1 Measurement types'!$B$2:$B$201,MATCH(D13,'1 Measurement types'!$A$2:$A$201,0))<>B13,"Kind does not match its measurement type",IF(AND(B13="Measurement",E13=""),"A measurement needs a unit",IF(AND(B13="Measurement",NOT(EXACT(E13,INDEX('1 Measurement types'!$C$2:$C$201,MATCH(D13,'1 Measurement types'!$A$2:$A$201,0))))),"Unit does not match its measurement type",IF(F13="","Give it a short name","ok")))))))))
... H201: =IF(A201="","",IF(SUMPRODUCT(--EXACT('3 Bindings'!$A$2:$A$201,A201))>0,"yes","not yet")) | I201: =IF(A201="","",IF(SUMPRODUCT(--EXACT($A$2:$A$201,A201))>1,"Duplicate ID",IF(AND(B201<>"Measurement",B201<>"State or alarm"),"Kind must be Measurement or State or alarm",IF(SUMPRODUCT(--EXACT('2 Assets'!$A$2:$A$201,C201))=0,"Asset is not on the Assets sheet",IF(SUMPRODUCT(--EXACT('1 Measurement types'!$A$2:$A$201,D201))=0,"Not on the Measurement types sheet",IF(INDEX('1 Measurement types'!$B$2:$B$201,MATCH(D201,'1 Measurement types'!$A$2:$A$201,0))<>B201,"Kind does not match its measurement type",IF(AND(B201="Measurement",E201=""),"A measurement needs a unit",IF(AND(B201="Measurement",NOT(EXACT(E201,INDEX('1 Measurement types'!$C$2:$C$201,MATCH(D201,'1 Measurement types'!$A$2:$A$201,0))))),"Unit does not match its measurement type",IF(F201="","Give it a short name","ok")))))))))

Sheet 2 Relationships
A1: From (asset ID) | B1: Relationship | C1: To (asset ID) | D1: Check (do not edit)
D2: =IF(A2="","",IF(SUMPRODUCT(--EXACT('2 Assets'!$A$2:$A$201,A2))=0,"'From' is not an asset",IF(SUMPRODUCT(--EXACT('2 Assets'!$A$2:$A$201,C2))=0,"'To' is not an asset",IF(SUMPRODUCT(--EXACT('1 Relationship types'!$A$2:$A$201,B2))=0,"Relationship is not defined",IF(A2=C2,"An asset cannot relate to itself",IF(SUMPRODUCT(--EXACT($A$2:$A$201,A2),--EXACT($B$2:$B$201,B2),--EXACT($C$2:$C$201,C2))>1,"Listed twice","ok"))))))
D3: =IF(A3="","",IF(SUMPRODUCT(--EXACT('2 Assets'!$A$2:$A$201,A3))=0,"'From' is not an asset",IF(SUMPRODUCT(--EXACT('2 Assets'!$A$2:$A$201,C3))=0,"'To' is not an asset",IF(SUMPRODUCT(--EXACT('1 Relationship types'!$A$2:$A$201,B3))=0,"Relationship is not defined",IF(A3=C3,"An asset cannot relate to itself",IF(SUMPRODUCT(--EXACT($A$2:$A$201,A3),--EXACT($B$2:$B$201,B3),--EXACT($C$2:$C$201,C3))>1,"Listed twice","ok"))))))
D4: =IF(A4="","",IF(SUMPRODUCT(--EXACT('2 Assets'!$A$2:$A$201,A4))=0,"'From' is not an asset",IF(SUMPRODUCT(--EXACT('2 Assets'!$A$2:$A$201,C4))=0,"'To' is not an asset",IF(SUMPRODUCT(--EXACT('1 Relationship types'!$A$2:$A$201,B4))=0,"Relationship is not defined",IF(A4=C4,"An asset cannot relate to itself",IF(SUMPRODUCT(--EXACT($A$2:$A$201,A4),--EXACT($B$2:$B$201,B4),--EXACT($C$2:$C$201,C4))>1,"Listed twice","ok"))))))
D5: =IF(A5="","",IF(SUMPRODUCT(--EXACT('2 Assets'!$A$2:$A$201,A5))=0,"'From' is not an asset",IF(SUMPRODUCT(--EXACT('2 Assets'!$A$2:$A$201,C5))=0,"'To' is not an asset",IF(SUMPRODUCT(--EXACT('1 Relationship types'!$A$2:$A$201,B5))=0,"Relationship is not defined",IF(A5=C5,"An asset cannot relate to itself",IF(SUMPRODUCT(--EXACT($A$2:$A$201,A5),--EXACT($B$2:$B$201,B5),--EXACT($C$2:$C$201,C5))>1,"Listed twice","ok"))))))
D6: =IF(A6="","",IF(SUMPRODUCT(--EXACT('2 Assets'!$A$2:$A$201,A6))=0,"'From' is not an asset",IF(SUMPRODUCT(--EXACT('2 Assets'!$A$2:$A$201,C6))=0,"'To' is not an asset",IF(SUMPRODUCT(--EXACT('1 Relationship types'!$A$2:$A$201,B6))=0,"Relationship is not defined",IF(A6=C6,"An asset cannot relate to itself",IF(SUMPRODUCT(--EXACT($A$2:$A$201,A6),--EXACT($B$2:$B$201,B6),--EXACT($C$2:$C$201,C6))>1,"Listed twice","ok"))))))
D7: =IF(A7="","",IF(SUMPRODUCT(--EXACT('2 Assets'!$A$2:$A$201,A7))=0,"'From' is not an asset",IF(SUMPRODUCT(--EXACT('2 Assets'!$A$2:$A$201,C7))=0,"'To' is not an asset",IF(SUMPRODUCT(--EXACT('1 Relationship types'!$A$2:$A$201,B7))=0,"Relationship is not defined",IF(A7=C7,"An asset cannot relate to itself",IF(SUMPRODUCT(--EXACT($A$2:$A$201,A7),--EXACT($B$2:$B$201,B7),--EXACT($C$2:$C$201,C7))>1,"Listed twice","ok"))))))
D8: =IF(A8="","",IF(SUMPRODUCT(--EXACT('2 Assets'!$A$2:$A$201,A8))=0,"'From' is not an asset",IF(SUMPRODUCT(--EXACT('2 Assets'!$A$2:$A$201,C8))=0,"'To' is not an asset",IF(SUMPRODUCT(--EXACT('1 Relationship types'!$A$2:$A$201,B8))=0,"Relationship is not defined",IF(A8=C8,"An asset cannot relate to itself",IF(SUMPRODUCT(--EXACT($A$2:$A$201,A8),--EXACT($B$2:$B$201,B8),--EXACT($C$2:$C$201,C8))>1,"Listed twice","ok"))))))
D9: =IF(A9="","",IF(SUMPRODUCT(--EXACT('2 Assets'!$A$2:$A$201,A9))=0,"'From' is not an asset",IF(SUMPRODUCT(--EXACT('2 Assets'!$A$2:$A$201,C9))=0,"'To' is not an asset",IF(SUMPRODUCT(--EXACT('1 Relationship types'!$A$2:$A$201,B9))=0,"Relationship is not defined",IF(A9=C9,"An asset cannot relate to itself",IF(SUMPRODUCT(--EXACT($A$2:$A$201,A9),--EXACT($B$2:$B$201,B9),--EXACT($C$2:$C$201,C9))>1,"Listed twice","ok"))))))
D10: =IF(A10="","",IF(SUMPRODUCT(--EXACT('2 Assets'!$A$2:$A$201,A10))=0,"'From' is not an asset",IF(SUMPRODUCT(--EXACT('2 Assets'!$A$2:$A$201,C10))=0,"'To' is not an asset",IF(SUMPRODUCT(--EXACT('1 Relationship types'!$A$2:$A$201,B10))=0,"Relationship is not defined",IF(A10=C10,"An asset cannot relate to itself",IF(SUMPRODUCT(--EXACT($A$2:$A$201,A10),--EXACT($B$2:$B$201,B10),--EXACT($C$2:$C$201,C10))>1,"Listed twice","ok"))))))
D11: =IF(A11="","",IF(SUMPRODUCT(--EXACT('2 Assets'!$A$2:$A$201,A11))=0,"'From' is not an asset",IF(SUMPRODUCT(--EXACT('2 Assets'!$A$2:$A$201,C11))=0,"'To' is not an asset",IF(SUMPRODUCT(--EXACT('1 Relationship types'!$A$2:$A$201,B11))=0,"Relationship is not defined",IF(A11=C11,"An asset cannot relate to itself",IF(SUMPRODUCT(--EXACT($A$2:$A$201,A11),--EXACT($B$2:$B$201,B11),--EXACT($C$2:$C$201,C11))>1,"Listed twice","ok"))))))
D12: =IF(A12="","",IF(SUMPRODUCT(--EXACT('2 Assets'!$A$2:$A$201,A12))=0,"'From' is not an asset",IF(SUMPRODUCT(--EXACT('2 Assets'!$A$2:$A$201,C12))=0,"'To' is not an asset",IF(SUMPRODUCT(--EXACT('1 Relationship types'!$A$2:$A$201,B12))=0,"Relationship is not defined",IF(A12=C12,"An asset cannot relate to itself",IF(SUMPRODUCT(--EXACT($A$2:$A$201,A12),--EXACT($B$2:$B$201,B12),--EXACT($C$2:$C$201,C12))>1,"Listed twice","ok"))))))
